/var/spool/slurmd/job1054557/slurm_script: line 17: conda: command not found
/var/spool/slurmd/job1054557/slurm_script: line 19: conda: command not found
/var/spool/slurmd/job1054557/slurm_script: line 26: activate: No such file or directory
WARNING: Retrying (Retry(total=4, connect=None, read=None, redirect=None, status=None)) after connection broken by 'NewConnectionError('<pip._vendor.urllib3.connection.HTTPSConnection object at 0x1510887fef10>: Failed to establish a new connection: [Errno 101] Network is unreachable')': /simple/datetime/
WARNING: Retrying (Retry(total=3, connect=None, read=None, redirect=None, status=None)) after connection broken by 'NewConnectionError('<pip._vendor.urllib3.connection.HTTPSConnection object at 0x1510887fec70>: Failed to establish a new connection: [Errno 101] Network is unreachable')': /simple/datetime/
WARNING: Retrying (Retry(total=2, connect=None, read=None, redirect=None, status=None)) after connection broken by 'NewConnectionError('<pip._vendor.urllib3.connection.HTTPSConnection object at 0x1510887fe6d0>: Failed to establish a new connection: [Errno 101] Network is unreachable')': /simple/datetime/
WARNING: Retrying (Retry(total=1, connect=None, read=None, redirect=None, status=None)) after connection broken by 'NewConnectionError('<pip._vendor.urllib3.connection.HTTPSConnection object at 0x151088800700>: Failed to establish a new connection: [Errno 101] Network is unreachable')': /simple/datetime/
WARNING: Retrying (Retry(total=0, connect=None, read=None, redirect=None, status=None)) after connection broken by 'NewConnectionError('<pip._vendor.urllib3.connection.HTTPSConnection object at 0x1510888008b0>: Failed to establish a new connection: [Errno 101] Network is unreachable')': /simple/datetime/
ERROR: Could not find a version that satisfies the requirement datetime (from versions: none)
ERROR: No matching distribution found for datetime
