/var/spool/slurmd/job1048293/slurm_script: line 13: conda: command not found
Loading pytorch-gpu/py3/1.12.1
  Loading requirement: cuda/11.2 nccl/2.9.6-1-cuda cudnn/8.1.1.33-cuda gcc/8.5.0
    openmpi/4.1.1-cuda intel-mkl/2020.4 magma/2.5.4-cuda-oneapi-mkl sox/14.4.2
    sparsehash/2.0.3 libjpeg-turbo/2.1.3
+ srun pip install -r requirements.txt
WARNING: Retrying (Retry(total=4, connect=None, read=None, redirect=None, status=None)) after connection broken by 'NewConnectionError('<pip._vendor.urllib3.connection.HTTPSConnection object at 0x149b851b44f0>: Failed to establish a new connection: [Errno 101] Network is unreachable')': /simple/datetime/
WARNING: Retrying (Retry(total=3, connect=None, read=None, redirect=None, status=None)) after connection broken by 'NewConnectionError('<pip._vendor.urllib3.connection.HTTPSConnection object at 0x149b851b4820>: Failed to establish a new connection: [Errno 101] Network is unreachable')': /simple/datetime/
WARNING: Retrying (Retry(total=2, connect=None, read=None, redirect=None, status=None)) after connection broken by 'NewConnectionError('<pip._vendor.urllib3.connection.HTTPSConnection object at 0x149b851b49d0>: Failed to establish a new connection: [Errno 101] Network is unreachable')': /simple/datetime/
WARNING: Retrying (Retry(total=1, connect=None, read=None, redirect=None, status=None)) after connection broken by 'NewConnectionError('<pip._vendor.urllib3.connection.HTTPSConnection object at 0x149b851b4b80>: Failed to establish a new connection: [Errno 101] Network is unreachable')': /simple/datetime/
WARNING: Retrying (Retry(total=0, connect=None, read=None, redirect=None, status=None)) after connection broken by 'NewConnectionError('<pip._vendor.urllib3.connection.HTTPSConnection object at 0x149b851b4d30>: Failed to establish a new connection: [Errno 101] Network is unreachable')': /simple/datetime/
ERROR: Could not find a version that satisfies the requirement datetime (from versions: none)
ERROR: No matching distribution found for datetime
WARNING: There was an error checking the latest version of pip.
srun: error: r3i4n0: task 0: Exited with exit code 1
srun: Terminating StepId=1048293.0
+ srun python -m src.evaluate --experiment-name jz_first_test --dataset kill --model google/flan-t5-small --question-types ab --eval-nb-samples 1 --dataset-folder paperlaws
Traceback (most recent call last):
  File "/gpfslocalsup/pub/anaconda-py3/2022.05/envs/pytorch-gpu-1.12.1+py3.10.4/lib/python3.10/runpy.py", line 196, in _run_module_as_main
    return _run_code(code, main_globals, None,
  File "/gpfslocalsup/pub/anaconda-py3/2022.05/envs/pytorch-gpu-1.12.1+py3.10.4/lib/python3.10/runpy.py", line 86, in _run_code
    exec(code, run_globals)
  File "/gpfsdswork/projects/rech/aho/uus79sn/llm_alignment/src/evaluate.py", line 8, in <module>
    from src.models import (
  File "/gpfsdswork/projects/rech/aho/uus79sn/llm_alignment/src/models.py", line 6, in <module>
    import ai21
ModuleNotFoundError: No module named 'ai21'
srun: error: r3i4n0: task 0: Exited with exit code 1
srun: Terminating StepId=1048293.1
